2018-12-18 10:53:58,122 ERROR: Exception on /login [GET] [in c:\python27\lib\site-packages\flask\app.py:1560]
Traceback (most recent call last):
  File "c:\python27\lib\site-packages\flask\app.py", line 1982, in wsgi_app
    response = self.full_dispatch_request()
  File "c:\python27\lib\site-packages\flask\app.py", line 1614, in full_dispatch_request
    rv = self.handle_user_exception(e)
  File "c:\python27\lib\site-packages\flask\app.py", line 1517, in handle_user_exception
    reraise(exc_type, exc_value, tb)
  File "c:\python27\lib\site-packages\flask\app.py", line 1612, in full_dispatch_request
    rv = self.dispatch_request()
  File "c:\python27\lib\site-packages\flask\app.py", line 1598, in dispatch_request
    return self.view_functions[rule.endpoint](**req.view_args)
  File "C:\Projects\Flask\FlaskWebApp\FlaskApp\app\routes.py", line 74, in login
    return render_template('login.html',title='Sign In', form = form)
  File "c:\python27\lib\site-packages\flask\templating.py", line 134, in render_template
    context, ctx.app)
  File "c:\python27\lib\site-packages\flask\templating.py", line 116, in _render
    rv = template.render(context)
  File "c:\python27\lib\site-packages\jinja2\environment.py", line 1008, in render
    return self.environment.handle_exception(exc_info, True)
  File "c:\python27\lib\site-packages\jinja2\environment.py", line 780, in handle_exception
    reraise(exc_type, exc_value, tb)
  File "C:\Projects\Flask\FlaskWebApp\FlaskApp\app\templates\login.html", line 2, in top-level template code
    {% import 'bootstrap/wtf.html' as wtf %}
  File "C:\Projects\Flask\FlaskWebApp\FlaskApp\app\templates\base.html", line 1, in top-level template code
    {% extends 'bootstrap/base.html' %}
  File "c:\python27\lib\site-packages\flask_bootstrap\templates\bootstrap\base.html", line 1, in top-level template code
    {% block doc -%}
  File "c:\python27\lib\site-packages\flask_bootstrap\templates\bootstrap\base.html", line 4, in block "doc"
    {%- block html %}
  File "c:\python27\lib\site-packages\flask_bootstrap\templates\bootstrap\base.html", line 20, in block "html"
    {% block body -%}
  File "c:\python27\lib\site-packages\flask_bootstrap\templates\bootstrap\base.html", line 21, in block "body"
    {% block navbar %}
  File "C:\Projects\Flask\FlaskWebApp\FlaskApp\app\templates\base.html", line 23, in block "navbar"
    <li><a href="{{ url_for('planner') }}">Planner</a></li>
  File "c:\python27\lib\site-packages\flask\helpers.py", line 333, in url_for
    return appctx.app.handle_url_build_error(error, endpoint, values)
  File "c:\python27\lib\site-packages\flask\app.py", line 1805, in handle_url_build_error
    reraise(exc_type, exc_value, tb)
  File "c:\python27\lib\site-packages\flask\helpers.py", line 323, in url_for
    force_external=external)
  File "c:\python27\lib\site-packages\werkzeug\routing.py", line 1776, in build
    raise BuildError(endpoint, values, method, self)
BuildError: Could not build url for endpoint 'planner'. Did you mean 'edit_planner' instead?
2018-12-18 10:54:03,068 ERROR: Exception on /login [GET] [in c:\python27\lib\site-packages\flask\app.py:1560]
Traceback (most recent call last):
  File "c:\python27\lib\site-packages\flask\app.py", line 1982, in wsgi_app
    response = self.full_dispatch_request()
  File "c:\python27\lib\site-packages\flask\app.py", line 1614, in full_dispatch_request
    rv = self.handle_user_exception(e)
  File "c:\python27\lib\site-packages\flask\app.py", line 1517, in handle_user_exception
    reraise(exc_type, exc_value, tb)
  File "c:\python27\lib\site-packages\flask\app.py", line 1612, in full_dispatch_request
    rv = self.dispatch_request()
  File "c:\python27\lib\site-packages\flask\app.py", line 1598, in dispatch_request
    return self.view_functions[rule.endpoint](**req.view_args)
  File "C:\Projects\Flask\FlaskWebApp\FlaskApp\app\routes.py", line 74, in login
    return render_template('login.html',title='Sign In', form = form)
  File "c:\python27\lib\site-packages\flask\templating.py", line 134, in render_template
    context, ctx.app)
  File "c:\python27\lib\site-packages\flask\templating.py", line 116, in _render
    rv = template.render(context)
  File "c:\python27\lib\site-packages\jinja2\environment.py", line 1008, in render
    return self.environment.handle_exception(exc_info, True)
  File "c:\python27\lib\site-packages\jinja2\environment.py", line 780, in handle_exception
    reraise(exc_type, exc_value, tb)
  File "C:\Projects\Flask\FlaskWebApp\FlaskApp\app\templates\login.html", line 2, in top-level template code
    {% import 'bootstrap/wtf.html' as wtf %}
  File "C:\Projects\Flask\FlaskWebApp\FlaskApp\app\templates\base.html", line 1, in top-level template code
    {% extends 'bootstrap/base.html' %}
  File "c:\python27\lib\site-packages\flask_bootstrap\templates\bootstrap\base.html", line 1, in top-level template code
    {% block doc -%}
  File "c:\python27\lib\site-packages\flask_bootstrap\templates\bootstrap\base.html", line 4, in block "doc"
    {%- block html %}
  File "c:\python27\lib\site-packages\flask_bootstrap\templates\bootstrap\base.html", line 20, in block "html"
    {% block body -%}
  File "c:\python27\lib\site-packages\flask_bootstrap\templates\bootstrap\base.html", line 21, in block "body"
    {% block navbar %}
  File "C:\Projects\Flask\FlaskWebApp\FlaskApp\app\templates\base.html", line 23, in block "navbar"
    <li><a href="{{ url_for('planner') }}">Planner</a></li>
  File "c:\python27\lib\site-packages\flask\helpers.py", line 333, in url_for
    return appctx.app.handle_url_build_error(error, endpoint, values)
  File "c:\python27\lib\site-packages\flask\app.py", line 1805, in handle_url_build_error
    reraise(exc_type, exc_value, tb)
  File "c:\python27\lib\site-packages\flask\helpers.py", line 323, in url_for
    force_external=external)
  File "c:\python27\lib\site-packages\werkzeug\routing.py", line 1776, in build
    raise BuildError(endpoint, values, method, self)
BuildError: Could not build url for endpoint 'planner'. Did you mean 'edit_planner' instead?
2018-12-18 10:55:24,536 INFO: FlaskApp [in C:\Projects\Flask\FlaskWebApp\FlaskApp\app\__init__.py:56]
2018-12-18 10:56:49,990 INFO: FlaskApp [in C:\Projects\Flask\FlaskWebApp\FlaskApp\app\__init__.py:56]
2018-12-18 10:58:10,464 INFO: FlaskApp [in C:\Projects\Flask\FlaskWebApp\FlaskApp\app\__init__.py:56]
2018-12-21 20:00:37,657 INFO: FlaskApp [in C:\Projects\Flask\FlaskWebApp\FlaskApp\app\__init__.py:56]
2019-02-16 12:22:42,176 INFO: FlaskApp [in C:\Projects\Flask\FlaskWebApp\FlaskApp\app\__init__.py:56]
2019-02-16 12:28:16,670 INFO: FlaskApp [in C:\Projects\Flask\FlaskWebApp\FlaskApp\app\__init__.py:56]
2019-02-16 12:28:31,243 ERROR: Exception on /index [GET] [in c:\python27\lib\site-packages\flask\app.py:1560]
Traceback (most recent call last):
  File "c:\python27\lib\site-packages\flask\app.py", line 1982, in wsgi_app
    response = self.full_dispatch_request()
  File "c:\python27\lib\site-packages\flask\app.py", line 1614, in full_dispatch_request
    rv = self.handle_user_exception(e)
  File "c:\python27\lib\site-packages\flask\app.py", line 1517, in handle_user_exception
    reraise(exc_type, exc_value, tb)
  File "c:\python27\lib\site-packages\flask\app.py", line 1612, in full_dispatch_request
    rv = self.dispatch_request()
  File "c:\python27\lib\site-packages\flask\app.py", line 1598, in dispatch_request
    return self.view_functions[rule.endpoint](**req.view_args)
  File "c:\python27\lib\site-packages\flask_login\utils.py", line 261, in decorated_view
    return func(*args, **kwargs)
  File "C:\Projects\Flask\FlaskWebApp\FlaskApp\app\routes.py", line 53, in index
    response = make_response(render_template('index.html', title='Home', form=form, pageForm = pageForm,
NameError: global name 'make_response' is not defined
2019-02-16 12:29:15,625 INFO: FlaskApp [in C:\Projects\Flask\FlaskWebApp\FlaskApp\app\__init__.py:56]
2019-02-16 12:33:53,184 INFO: FlaskApp [in C:\Projects\Flask\FlaskWebApp\FlaskApp\app\__init__.py:56]
2019-02-16 12:36:39,868 INFO: FlaskApp [in C:\Projects\Flask\FlaskWebApp\FlaskApp\app\__init__.py:56]
2019-02-16 12:39:12,171 INFO: FlaskApp [in C:\Projects\Flask\FlaskWebApp\FlaskApp\app\__init__.py:56]
2019-02-16 12:42:57,698 INFO: FlaskApp [in C:\Projects\Flask\FlaskWebApp\FlaskApp\app\__init__.py:56]
2019-02-16 12:44:05,907 INFO: FlaskApp [in C:\Projects\Flask\FlaskWebApp\FlaskApp\app\__init__.py:56]
